<?xml version='1.0'?>
<sdf version='1.7'>
  <model name='blindenhund'>
    <link name='base_footprint'>
      <self_collide>0</self_collide>
      <inertial>
        <pose>0 0 0 0 -0 0</pose>
        <inertia>
          <ixx>1</ixx>
          <ixy>0</ixy>
          <ixz>0</ixz>
          <iyy>1</iyy>
          <iyz>0</iyz>
          <izz>1</izz>
        </inertia>
        <mass>0</mass>
      </inertial>
      <enable_wind>0</enable_wind>
      <kinematic>0</kinematic>
      <pose>0 0 0 0 -0 0</pose>
      <gravity>1</gravity>
    </link>
    
    <link name='base_link'>
      <inertial>
        <pose>0.3576 0 0.3024 0 0 0</pose>
        <mass>8</mass>
        <inertia>
          <ixx>0.01</ixx>
          <ixy>0</ixy>
          <ixz>0</ixz>
          <iyy>0.1</iyy>
          <iyz>0</iyz>
          <izz>0.1</izz>
        </inertia>
      </inertial>
      <self_collide>0</self_collide>
      <enable_wind>0</enable_wind>
      <kinematic>0</kinematic>
      <pose>0.3576 0 0.1524 0 -0 0</pose>
      <gravity>1</gravity>
      <visual name='base_visual'>
        <geometry>
          <box>
            <size>0.7152 0.628 0.30</size>
          </box>
        </geometry>
      </visual>
      <collision name='base_collision'>
        <max_contacts>10</max_contacts>
        <pose>0 0 0 0 0 0</pose>
        <geometry>
          <box>
            <size>0.7152 0.628 0.30</size>
          </box>
        </geometry>
      </collision>
    </link>
   
   <link name='left_wheel'>
      <inertial>
        <pose>0 0.3493 0 -1.5707 0 0</pose>
        <mass>0.5</mass>
        <inertia>
          <ixx>0.145833</ixx>
          <ixy>0</ixy>
          <ixz>0</ixz>
          <iyy>0.145833</iyy>
          <iyz>0</iyz>
          <izz>0.125</izz>
        </inertia>
      </inertial>
      <self_collide>0</self_collide>
      <enable_wind>0</enable_wind>
      <kinematic>0</kinematic>
      <pose>0 0 0 0 0 0</pose>
      <visual name='visual'>
        <pose>0 0.3493 0 -1.5707 0 0</pose>
        <geometry>
          <cylinder>
            <radius>0.1524</radius>
            <length>0.056</length>
          </cylinder>
        </geometry>
      </visual>
      <collision name='collision'>
        <pose>0 0.3493 0 -1.5707 0 0</pose>
        <max_contacts>10</max_contacts>
        <geometry>
          <cylinder>
            <radius>0.1524</radius>
            <length>0.056</length>
          </cylinder>
        </geometry>
        <surface>
          <friction>
            <ode>
              <mu>1</mu>
              <mu2>1</mu2>
              <slip1>0</slip1>
              <slip2>0</slip2>
            </ode>
          </friction>
          <contact>
            <ode>
              <soft_cfm>0</soft_cfm>
              <soft_erp>0.2</soft_erp>
              <kp>1e+13</kp>
              <kd>1</kd>
              <max_vel>0.01</max_vel>
              <min_depth>0.01</min_depth>
            </ode>
          </contact>
        </surface>
      </collision>
    </link>

    <link name='right_wheel'>
      <inertial>
        <pose>0 -0.3493 0 -1.5707 0 0</pose>
        <mass>0.5</mass>
        <inertia>
          <ixx>0.145833</ixx>
          <ixy>0</ixy>
          <ixz>0</ixz>
          <iyy>0.145833</iyy>
          <iyz>0</iyz>
          <izz>0.125</izz>
        </inertia>
      </inertial>
      <self_collide>0</self_collide>
      <enable_wind>0</enable_wind>
      <kinematic>0</kinematic>
      <pose>0 0 0 0 -0 0</pose>
      <visual name='visual'>
        <pose>0 -0.3493 0 -1.5707 0 0</pose>
        <geometry>
          <cylinder>
            <radius>0.1524</radius>
            <length>0.056</length>
          </cylinder>
        </geometry>
      </visual>
      <collision name='collision'>
        <pose>0 -0.3493 0 -1.5707 0 0</pose>
        <max_contacts>10</max_contacts>
        <geometry>
          <cylinder>
            <radius>0.1524</radius>
            <length>0.056</length>
          </cylinder>
        </geometry>
        <surface>
          <friction>
            <ode>
              <mu>1</mu>
              <mu2>1</mu2>
              <slip1>0</slip1>
              <slip2>0</slip2>
            </ode>
          </friction>
          <contact>
            <ode>
              <soft_cfm>0</soft_cfm>
              <soft_erp>0.2</soft_erp>
              <kp>1e+13</kp>
              <kd>1</kd>
              <max_vel>0.01</max_vel>
              <min_depth>0.01</min_depth>
            </ode>
          </contact>
        </surface>
      </collision>
    </link>

   
    <link name='left_grip'>
      <pose>0 0.294 0.3988 0 0 0</pose>
      <inertial>
        <mass>0.2</mass>
        <inertia>
          <ixx>0.145833</ixx>
          <ixy>0</ixy>
          <ixz>0</ixz>
          <iyy>0.145833</iyy>
          <iyz>0</iyz>
          <izz>0.125</izz>
        </inertia>
        <pose>0 0 0 0 -0 0</pose>
      </inertial>
      <visual name='visual'>
        <geometry>
          <cylinder>
            <radius>0.02</radius>
            <length>0.7976</length>
          </cylinder>
        </geometry>
        <pose>0 0 0 0 -0 0</pose>
      </visual>
      <collision name='collision'>
        <max_contacts>10</max_contacts>
        <pose>0 0 0 0 -0 0</pose>
        <geometry>
          <cylinder>
            <radius>0.02</radius>
            <length>0.7976</length>
          </cylinder>
        </geometry>
      </collision>
    </link>
   
    <link name='right_grip'>
      <pose>0 -0.294 0.3988 0 0 0</pose>
      <inertial>
        <mass>0.2</mass>
        <inertia>
          <ixx>0.145833</ixx>
          <ixy>0</ixy>
          <ixz>0</ixz>
          <iyy>0.145833</iyy>
          <iyz>0</iyz>
          <izz>0.125</izz>
        </inertia>
        <pose>0 0 0 0 -0 0</pose>
      </inertial>
      <visual name='visual'>
        <geometry>
          <cylinder>
            <radius>0.02</radius>
            <length>0.7976</length>
          </cylinder>
        </geometry>
        <pose>0 0 0 0 -0 0</pose>
      </visual>
      <collision name='collision'>
        <max_contacts>10</max_contacts>
        <pose>0 0 0 0 -0 0</pose>
        <geometry>
          <cylinder>
            <radius>0.02</radius>
            <length>0.7976</length>
          </cylinder>
        </geometry>
      </collision>
    </link>

    <link name='imu_link'>
      <sensor name='tb3_imu' type='imu'>
        <always_on>true</always_on>
        <update_rate>200</update_rate>
        <imu>
          <angular_velocity>
            <x>
              <noise type='gaussian'>
                <mean>0.0</mean>
                <stddev>2e-4</stddev>
              </noise>
            </x>
            <y>
              <noise type='gaussian'>
                <mean>0.0</mean>
                <stddev>2e-4</stddev>
              </noise>
            </y>
            <z>
              <noise type='gaussian'>
                <mean>0.0</mean>
                <stddev>2e-4</stddev>
              </noise>
            </z>
          </angular_velocity>
          <linear_acceleration>
            <x>
              <noise type='gaussian'>
                <mean>0.0</mean>
                <stddev>1.7e-2</stddev>
              </noise>
            </x>
            <y>
              <noise type='gaussian'>
                <mean>0.0</mean>
                <stddev>1.7e-2</stddev>
              </noise>
            </y>
            <z>
              <noise type='gaussian'>
                <mean>0.0</mean>
                <stddev>1.7e-2</stddev>
              </noise>
            </z>
          </linear_acceleration>
        </imu>
        <plugin name='blindenhund_imu' filename='libgazebo_ros_imu_sensor.so'>
          <ros>
            <remapping>~/out:=imu</remapping>
          </ros>
        </plugin>
      </sensor>
      <self_collide>0</self_collide>
      <inertial>
        <pose>0 0 0 0 -0 0</pose>
        <inertia>
          <ixx>1</ixx>
          <ixy>0</ixy>
          <ixz>0</ixz>
          <iyy>1</iyy>
          <iyz>0</iyz>
          <izz>1</izz>
        </inertia>
        <mass>0.001</mass>
      </inertial>
      <enable_wind>0</enable_wind>
      <kinematic>0</kinematic>
      <pose>0 0 0 0 -0 0</pose>
    </link>

    
    <link name='caster'>
      <pose>0.7152 0 0 0 0 0</pose>
      <inertial>
        <mass>2</mass>
        <inertia>
          <ixx>0.1</ixx>
          <ixy>0</ixy>
          <ixz>0</ixz>
          <iyy>0.1</iyy>
          <iyz>0</iyz>
          <izz>0.1</izz>
        </inertia>
        <pose>0 0 0 0 -0 0</pose>
      </inertial>
      <visual name='visual'>
        <geometry>
          <sphere>
            <radius>0.1524</radius>
          </sphere>
        </geometry>
        <pose>0 0 0 0 -0 0</pose>
      </visual>
      <collision name='collision'>
        <max_contacts>10</max_contacts>
        <pose>0 0 0 0 -0 0</pose>
        <geometry>
          <sphere>
            <radius>0.1524</radius>
          </sphere>
        </geometry>
        <surface>
          <contact>
            <ode>
              <soft_cfm>0</soft_cfm>
              <soft_erp>0.2</soft_erp>
              <kp>1e+5</kp>
              <kd>1</kd>
              <max_vel>0.01</max_vel>
              <min_depth>0.001</min_depth>
            </ode>
          </contact>
        </surface>
      </collision>
    </link>
    
    <link name='camera_link'>
      <inertial>
        <pose>0.75 -0.065 0.2 0 -0 0</pose>
        <inertia>
          <ixx>0.001</ixx>
          <ixy>0.000</ixy>
          <ixz>0.000</ixz>
          <iyy>0.001</iyy>
          <iyz>0.000</iyz>
          <izz>0.001</izz>
        </inertia>
        <mass>0.035</mass>
      </inertial>
      <pose>0.75 -0.065 0.2 0 -0 0</pose>
      <sensor name='intel_realsense_r200_depth' type='depth'>
        <always_on>1</always_on>
        <update_rate>5</update_rate>
        <pose>0.064 -0.047 0.2 0 0 0</pose>
        <camera name='realsense_depth_camera'>
          <horizontal_fov>1.047</horizontal_fov>
          <image>
            <width>320</width>
            <height>240</height>
          </image>
          <clip>
            <near>0.1</near>
            <far>100</far>
          </clip>
        </camera>
        <plugin name='intel_realsense_r200_depth_driver' filename='libgazebo_ros_camera.so'>
          <ros>
          </ros>
          <camera_name>intel_realsense_r200_depth</camera_name>
          <frame_name>camera_depth_frame</frame_name>
          <hack_baseline>0.07</hack_baseline>
          <min_depth>0.001</min_depth>
          <max_depth>5.0</max_depth>
        </plugin>
      </sensor>
      <pose>0.069 -0.047 0.2 0 -0 0</pose>
      <self_collide>0</self_collide>
      <enable_wind>0</enable_wind>
      <kinematic>0</kinematic>
      <gravity>1</gravity>
      <collision name='collision'>
        <pose>0 0.047 -0.005 0 0 0</pose>
        <geometry>
          <box>
            <size>0.008 0.130 0.022</size>
          </box>
        </geometry>
      </collision>
      <pose>0.069 -0.047 0.2 0 0 0</pose>
    </link>    
    
    <link name='base_scan'>
      <inertial>
        <pose>0.6 0 0.32 0 -0 0</pose>
        <mass>0.2</mass>
        <inertia>
          <ixx>0.001</ixx>
          <ixy>0</ixy>
          <ixz>0</ixz>
          <iyy>0.01</iyy>
          <iyz>0</iyz>
          <izz>0.01</izz>
        </inertia>
      </inertial>
      <visual name='lidar_sensor_visual'>
        <geometry>
          <mesh>
            <uri>model://blindenhund/meshes/lds.dae</uri>
            <scale>0.001 0.001 0.001</scale>
          </mesh>
        </geometry>
        <pose>0 0 0 0 -0 0</pose>
      </visual>
      <collision name='lidar_sensor_collision'>
        <max_contacts>10</max_contacts>
        <pose>0 0 0 0 -0 0</pose>
        <geometry>
          <box>
            <size>0.1 0.1 0.2</size>
          </box>
        </geometry>
      </collision>
<!-- ray sensor -->
      <sensor name='sick_tim5xx' type='ray'>
        <always_on>1</always_on>
        <visualize>1</visualize>
        <pose>0 0 0 0 0 0</pose>
        <update_rate>15</update_rate>
        <ray>
          <scan>
            <horizontal>
              <samples>810</samples>
              <resolution>0.33</resolution>
              <min_angle>-2.3562</min_angle>
              <max_angle>2.3562</max_angle>
            </horizontal>
            <vertical>
              <samples>1</samples>
              <min_angle>0</min_angle>
              <max_angle>0</max_angle>
            </vertical>
          </scan>
          <range>
            <min>0.05</min>
            <max>25</max>
            <resolution>0.06</resolution>
          </range>
          <noise>
            <type>gaussian</type>
            <mean>0.0</mean>
            <stddev>0.01</stddev>
          </noise>
        </ray>
        <plugin name='sick_laserscan' filename='libgazebo_ros_ray_sensor.so'>
          <ros>
            <remapping>~/out:=scan</remapping>
          </ros>
          <output_type>sensor_msgs/LaserScan</output_type>
          <frameName>base_scan</frameName>
        </plugin>
      </sensor>
      <self_collide>0</self_collide>
      <enable_wind>0</enable_wind>
      <kinematic>0</kinematic>
      <pose>0.6 -0 0.32 0 -0 0</pose>
      <gravity>1</gravity>
    </link>
    
    <joint name='base_joint' type='fixed'>
      <parent>base_footprint</parent>
      <child>base_link</child>
      <pose>0.0 0.0 0.0 0 0 0</pose>
    </joint>
    
    <joint name='left_grip_joint' type='fixed'>
      <parent>base_footprint</parent>
      <child>left_grip</child>
      <pose>0 0 0 0 -0 0</pose>
    </joint>

    <joint name='right_grip_joint' type='fixed'>
      <parent>base_link</parent>
      <child>right_grip</child>
      <pose>0 0 0 0 -0 0</pose>
    </joint>

    <joint name='left_wheel_joint' type='revolute'>
      <parent>base_link</parent>
      <child>left_wheel</child>
      <pose>0 0 0 0 0 0</pose>
      <axis>
        <xyz>0 0 1</xyz>
        <limit>
          <lower>-1e+16</lower>
          <upper>1e+16</upper>
          <effort>-1</effort>
          <velocity>-1</velocity>
        </limit>
        <dynamics>
          <spring_reference>0</spring_reference>
          <spring_stiffness>0</spring_stiffness>
          <damping>0</damping>
          <friction>0</friction>
        </dynamics>
      </axis>
    </joint>

    <joint name='right_wheel_joint' type='revolute'>
      <parent>base_link</parent>
      <child>right_wheel</child>
      <pose>0 0 0 0 0 0</pose>
      <axis>
        <xyz>0 0 1</xyz>
        <limit>
          <lower>-1e+16</lower>
          <upper>1e+16</upper>
          <effort>-1</effort>
          <velocity>-1</velocity>
        </limit>
        <dynamics>
          <spring_reference>0</spring_reference>
          <spring_stiffness>0</spring_stiffness>
          <damping>0</damping>
          <friction>0</friction>
        </dynamics>
      </axis>
    </joint>

    <joint name='caster_wheel' type='ball'>
      <parent>base_link</parent>
      <child>caster</child>
      <pose>0 0 0 0 -0 0</pose>
    </joint>
    
    <joint name='sensor_joint' type='fixed'>
      <parent>base_link</parent>
      <child>base_scan</child>
      <pose>-0.064 0 0.130 0 0 0</pose>
    </joint>
    
    <joint name='camera_joint' type='fixed'>
      <parent>base_link</parent>
      <child>camera_link</child>
      <pose>0.064 -0.065 0.094 0 0 0</pose>
    </joint>

    <joint name='camera_rgb_joint' type='fixed'>
      <parent>camera_link</parent>
      <child>camera_rgb_frame</child>
      <pose>0.005 0.018 0.013 0 0 0</pose>
      <axis>
        <xyz>0 0 1</xyz>
      </axis>
    </joint>
    
    <plugin name='diff_drive' filename='libgazebo_ros_diff_drive.so'>

      <ros>
        <!--namespace>/demo</namespace>
        <remapping>cmd_vel:=cmd_demo</remapping>
        <remapping>odom:=odom_demo</remapping-->
      </ros>
      
      <update_rate>30</update_rate>
      
      <!-- wheels -->
      <left_joint>left_wheel_joint</left_joint>
      <right_joint>right_wheel_joint</right_joint>

      <!-- kinematics -->
      <wheel_separation>0.648</wheel_separation>
      <wheel_diameter>0.3048</wheel_diameter>

      <!-- limits -->
      <max_wheel_torque>10</max_wheel_torque>
      <max_wheel_acceleration>0.5</max_wheel_acceleration>

      <command_topic>cmd_vel</command_topic>

      <!-- output -->
      <publish_odom>true</publish_odom>
      <publish_odom_tf>true</publish_odom_tf>
      <publish_wheel_tf>false</publish_wheel_tf>
      
      <odometry_topic>odom</odometry_topic>
      <odometry_frame>odom</odometry_frame>
      <robot_base_frame>base_footprint</robot_base_frame>

    </plugin>
    
    <plugin name='blindenhund_joint_state' filename='libgazebo_ros_joint_state_publisher.so'>
      <ros>
        <!-- <namespace>/tb3</namespace> -->
        <remapping>~/out:=joint_states</remapping>
      </ros>
      <update_rate>30</update_rate>
      <joint_name>left_wheel_joint</joint_name>
      <joint_name>right_wheel_joint</joint_name>
    </plugin>

  </model>
</sdf>
